[2024-12-05T20:05:09.468+0000] {taskinstance.py:1165} INFO - Dependencies all met for <TaskInstance: dummy_dag.Email_in manual__2024-12-05T20:02:55.191856+00:00 [queued]>
[2024-12-05T20:05:09.484+0000] {taskinstance.py:1165} INFO - Dependencies all met for <TaskInstance: dummy_dag.Email_in manual__2024-12-05T20:02:55.191856+00:00 [queued]>
[2024-12-05T20:05:09.485+0000] {taskinstance.py:1362} INFO - 
--------------------------------------------------------------------------------
[2024-12-05T20:05:09.486+0000] {taskinstance.py:1363} INFO - Starting attempt 1 of 2
[2024-12-05T20:05:09.487+0000] {taskinstance.py:1364} INFO - 
--------------------------------------------------------------------------------
[2024-12-05T20:05:09.506+0000] {taskinstance.py:1383} INFO - Executing <Task(EmailOperator): Email_in> on 2024-12-05 20:02:55.191856+00:00
[2024-12-05T20:05:09.515+0000] {standard_task_runner.py:55} INFO - Started process 235 to run task
[2024-12-05T20:05:09.518+0000] {standard_task_runner.py:82} INFO - Running: ['***', 'tasks', 'run', 'dummy_dag', 'Email_in', 'manual__2024-12-05T20:02:55.191856+00:00', '--job-id', '2271', '--raw', '--subdir', 'DAGS_FOLDER/demo.py', '--cfg-path', '/tmp/tmppu7u8o23']
[2024-12-05T20:05:09.519+0000] {standard_task_runner.py:83} INFO - Job 2271: Subtask Email_in
[2024-12-05T20:05:09.703+0000] {task_command.py:376} INFO - Running <TaskInstance: dummy_dag.Email_in manual__2024-12-05T20:02:55.191856+00:00 [running]> on host ece2bbff80df
[2024-12-05T20:05:09.904+0000] {taskinstance.py:1592} INFO - Exporting the following env vars:
AIRFLOW_CTX_DAG_OWNER=***
AIRFLOW_CTX_DAG_ID=dummy_dag
AIRFLOW_CTX_TASK_ID=Email_in
AIRFLOW_CTX_EXECUTION_DATE=2024-12-05T20:02:55.191856+00:00
AIRFLOW_CTX_TRY_NUMBER=1
AIRFLOW_CTX_DAG_RUN_ID=manual__2024-12-05T20:02:55.191856+00:00
[2024-12-05T20:05:09.923+0000] {warnings.py:110} WARNING - /home/***/.local/lib/python3.7/site-packages/***/utils/email.py:120: RemovedInAirflow3Warning: Fetching SMTP credentials from configuration variables will be deprecated in a future release. Please set credentials using a connection instead.
  send_mime_email(e_from=mail_from, e_to=recipients, mime_msg=msg, conn_id=conn_id, dryrun=dryrun)

[2024-12-05T20:05:09.924+0000] {configuration.py:569} WARNING - section/key [smtp/smtp_user] not found in config
[2024-12-05T20:05:09.924+0000] {email.py:229} INFO - Email alerting: attempt 1
[2024-12-05T20:05:09.925+0000] {taskinstance.py:1851} ERROR - Task failed with exception
Traceback (most recent call last):
  File "/home/airflow/.local/lib/python3.7/site-packages/airflow/operators/email.py", line 87, in execute
    custom_headers=self.custom_headers,
  File "/home/airflow/.local/lib/python3.7/site-packages/airflow/utils/email.py", line 72, in send_email
    **kwargs,
  File "/home/airflow/.local/lib/python3.7/site-packages/airflow/utils/email.py", line 120, in send_email_smtp
    send_mime_email(e_from=mail_from, e_to=recipients, mime_msg=msg, conn_id=conn_id, dryrun=dryrun)
  File "/home/airflow/.local/lib/python3.7/site-packages/airflow/utils/email.py", line 231, in send_mime_email
    smtp_conn = _get_smtp_connection(smtp_host, smtp_port, smtp_timeout, smtp_ssl)
  File "/home/airflow/.local/lib/python3.7/site-packages/airflow/utils/email.py", line 265, in _get_smtp_connection
    else smtplib.SMTP(host=host, port=port, timeout=timeout)
  File "/usr/local/lib/python3.7/smtplib.py", line 251, in __init__
    (code, msg) = self.connect(host, port)
  File "/usr/local/lib/python3.7/smtplib.py", line 336, in connect
    self.sock = self._get_socket(host, port, self.timeout)
  File "/usr/local/lib/python3.7/smtplib.py", line 307, in _get_socket
    self.source_address)
  File "/usr/local/lib/python3.7/socket.py", line 728, in create_connection
    raise err
  File "/usr/local/lib/python3.7/socket.py", line 716, in create_connection
    sock.connect(sa)
ConnectionRefusedError: [Errno 111] Connection refused
[2024-12-05T20:05:09.933+0000] {taskinstance.py:1406} INFO - Marking task as UP_FOR_RETRY. dag_id=dummy_dag, task_id=Email_in, execution_date=20241205T200255, start_date=20241205T200509, end_date=20241205T200509
[2024-12-05T20:05:09.946+0000] {standard_task_runner.py:105} ERROR - Failed to execute job 2271 for task Email_in ([Errno 111] Connection refused; 235)
[2024-12-05T20:05:09.989+0000] {local_task_job.py:164} INFO - Task exited with return code 1
[2024-12-05T20:05:10.013+0000] {local_task_job.py:273} INFO - 0 downstream tasks scheduled from follow-on schedule check
