[2024-12-08T07:13:37.266+0000] {taskinstance.py:1165} INFO - Dependencies all met for <TaskInstance: dummy_dag.Email_inn manual__2024-12-08T07:11:30.266720+00:00 [queued]>
[2024-12-08T07:13:37.280+0000] {taskinstance.py:1165} INFO - Dependencies all met for <TaskInstance: dummy_dag.Email_inn manual__2024-12-08T07:11:30.266720+00:00 [queued]>
[2024-12-08T07:13:37.281+0000] {taskinstance.py:1362} INFO - 
--------------------------------------------------------------------------------
[2024-12-08T07:13:37.283+0000] {taskinstance.py:1363} INFO - Starting attempt 2 of 2
[2024-12-08T07:13:37.284+0000] {taskinstance.py:1364} INFO - 
--------------------------------------------------------------------------------
[2024-12-08T07:13:37.301+0000] {taskinstance.py:1383} INFO - Executing <Task(EmailOperator): Email_inn> on 2024-12-08 07:11:30.266720+00:00
[2024-12-08T07:13:37.307+0000] {standard_task_runner.py:55} INFO - Started process 2552 to run task
[2024-12-08T07:13:37.311+0000] {standard_task_runner.py:82} INFO - Running: ['***', 'tasks', 'run', 'dummy_dag', 'Email_inn', 'manual__2024-12-08T07:11:30.266720+00:00', '--job-id', '2284', '--raw', '--subdir', 'DAGS_FOLDER/demo.py', '--cfg-path', '/tmp/tmpsvayy1db']
[2024-12-08T07:13:37.311+0000] {standard_task_runner.py:83} INFO - Job 2284: Subtask Email_inn
[2024-12-08T07:13:37.388+0000] {task_command.py:376} INFO - Running <TaskInstance: dummy_dag.Email_inn manual__2024-12-08T07:11:30.266720+00:00 [running]> on host ece2bbff80df
[2024-12-08T07:13:37.468+0000] {taskinstance.py:1592} INFO - Exporting the following env vars:
AIRFLOW_CTX_DAG_OWNER=***
AIRFLOW_CTX_DAG_ID=dummy_dag
AIRFLOW_CTX_TASK_ID=Email_inn
AIRFLOW_CTX_EXECUTION_DATE=2024-12-08T07:11:30.266720+00:00
AIRFLOW_CTX_TRY_NUMBER=2
AIRFLOW_CTX_DAG_RUN_ID=manual__2024-12-08T07:11:30.266720+00:00
[2024-12-08T07:13:37.480+0000] {warnings.py:110} WARNING - /home/***/.local/lib/python3.7/site-packages/***/utils/email.py:120: RemovedInAirflow3Warning: Fetching SMTP credentials from configuration variables will be deprecated in a future release. Please set credentials using a connection instead.
  send_mime_email(e_from=mail_from, e_to=recipients, mime_msg=msg, conn_id=conn_id, dryrun=dryrun)

[2024-12-08T07:13:37.481+0000] {configuration.py:569} WARNING - section/key [smtp/smtp_user] not found in config
[2024-12-08T07:13:37.482+0000] {email.py:229} INFO - Email alerting: attempt 1
[2024-12-08T07:13:37.483+0000] {taskinstance.py:1851} ERROR - Task failed with exception
Traceback (most recent call last):
  File "/home/airflow/.local/lib/python3.7/site-packages/airflow/operators/email.py", line 87, in execute
    custom_headers=self.custom_headers,
  File "/home/airflow/.local/lib/python3.7/site-packages/airflow/utils/email.py", line 72, in send_email
    **kwargs,
  File "/home/airflow/.local/lib/python3.7/site-packages/airflow/utils/email.py", line 120, in send_email_smtp
    send_mime_email(e_from=mail_from, e_to=recipients, mime_msg=msg, conn_id=conn_id, dryrun=dryrun)
  File "/home/airflow/.local/lib/python3.7/site-packages/airflow/utils/email.py", line 231, in send_mime_email
    smtp_conn = _get_smtp_connection(smtp_host, smtp_port, smtp_timeout, smtp_ssl)
  File "/home/airflow/.local/lib/python3.7/site-packages/airflow/utils/email.py", line 265, in _get_smtp_connection
    else smtplib.SMTP(host=host, port=port, timeout=timeout)
  File "/usr/local/lib/python3.7/smtplib.py", line 251, in __init__
    (code, msg) = self.connect(host, port)
  File "/usr/local/lib/python3.7/smtplib.py", line 336, in connect
    self.sock = self._get_socket(host, port, self.timeout)
  File "/usr/local/lib/python3.7/smtplib.py", line 307, in _get_socket
    self.source_address)
  File "/usr/local/lib/python3.7/socket.py", line 728, in create_connection
    raise err
  File "/usr/local/lib/python3.7/socket.py", line 716, in create_connection
    sock.connect(sa)
ConnectionRefusedError: [Errno 111] Connection refused
[2024-12-08T07:13:37.493+0000] {taskinstance.py:1406} INFO - Marking task as FAILED. dag_id=dummy_dag, task_id=Email_inn, execution_date=20241208T071130, start_date=20241208T071337, end_date=20241208T071337
[2024-12-08T07:13:37.507+0000] {standard_task_runner.py:105} ERROR - Failed to execute job 2284 for task Email_inn ([Errno 111] Connection refused; 2552)
[2024-12-08T07:13:37.523+0000] {local_task_job.py:164} INFO - Task exited with return code 1
[2024-12-08T07:13:37.552+0000] {local_task_job.py:273} INFO - 0 downstream tasks scheduled from follow-on schedule check
